---
source: tests/it/remote_git.rs
expression: "git::repository::Repository::update_clones(path,\n        integration).expect_err(\"Could not read from remote repository\")"
info: cloning private repo with bad auth
---
running git command
├╴at {source location}
╰╴context: running git command ["ls-remote", "--quiet"], status was: exit status: 128, stderr: ERROR: Repository not found.
  fatal: Could not read from remote repository.
  
  Please make sure you have the correct access rights
  and the repository exists.
