---
source: tests/it/remote_git.rs
expression: "integration.clone_reference(&reference).expect_err(\"Could not read from remote repository\")"
info: cloning private repo with bad auth
---
run external command
├╴at {source location}
│
╰─▶ git execution failed
    ├╴at {source location}
    ╰╴context: running git command ["-c", "credential.helper=", "clone", "--filter=blob:none", "--branch", "main", "http://github.com/github/doesnotexist.git", "{tmpdir}"], status was: exit status: 128, stderr: Cloning into '{tmpdir}'...
      remote: Repository not found.
      fatal: Authentication failed for 'https://github.com/github/doesnotexist.git/'
