---
source: tests/it/remote_git.rs
expression: "integration.references().expect_err(\"no results returned from get_references_that_need_scanning on a private repo\")"
info: references on private repo with bad auth
---
run external command
├╴at {source location}
│
╰─▶ git execution failed
    ├╴at {source location}
    ╰╴context: running git command ["-c", "credential.helper=", "ls-remote", "--quiet"], status was: exit status: 128, stderr: remote: Repository not found.
      fatal: Authentication failed for 'https://github.com/github/doesnotexist.git/'
