---
source: tests/it/remote_git.rs
expression: err
info: references on private repo with bad auth
---
run external command
├╴at {source location}
│
├─▶ IO layer error
│   ╰╴at {source location}
│
╰─▶ git execution failed
    ├╴at {source location}
    ╰╴context: running git command ["-c", "credential.helper=", "ls-remote", "--quiet"], status was: exit status: 128, stderr: fatal: could not read Username for 'https://github.com': terminal prompts disabled
